Workbook

Sheet Leads
A1: Lead ID | B1: Company Name | C1: Contact Name | D1: Email | E1: Website | F1: Industry | G1: Personalised Intro | H1: Service Assigned | I1: Current Campaign | J1: Email 1 Sent | K1: Follow-up 1 Sent | L1: Follow-up 2 Sent | M1: Follow-up 3 Sent | N1: Last Email Date | O1: Status | P1: Gmail Thread ID | Q1: Notes | R1: Last Updated
A2: 1 | B2: Tiwari Enterprises | C2: Divyan | D2: divyantiwariuni4@gmail.com | E2: https://djgam454.github.io/Portfolio-Website/ | F2: Personal Portfolio | G2: For personal portfolio sites like Tiwari Enterprises, ensuring potential clients can easily find your work through search is always a priority. | H2: SEO | I2: Service 2 | J2: 46233.542 | N2: 46233.542 | O2: DO_NOT_CONTACT | P2: 19fb1eecca78786b | R2: 46233.542
A3: 2 | B3: A Pharma | C3: Aryan | D3: aryandivyan@gmail.com | E3: https://mchemist.com/ | F3: Pharmacy | G3: Operating in the pharmacy sector involves balancing digital access with reliable patient communication. | H3: Website Development | I3: Service 1 | O3: DO_NOT_CONTACT | R3: 46233.442
A4: 999 | B4: Test Invalid | C4: Invalid Test | D4: this-is-not-an-email | G4: yes | H4: Website Development | I4: Service 1 | O4: INVALID | R4: 46231.461
A5: 998 | B5: Bounce Test | C5: Test Bounce | D5: nonexistent@your-test-domain.example | G5: hi | H5: Website Development | I5: Service 1 | J5: 46231.461 | N5: 46231.461 | O5: INVALID | R5: 46232.642
A6: 3 | B6: Dynamisers | C6: Sudipti | D6: dynamisers@gmail.com | E6: https://www.dynamisers.com/ | G6: As an agency scaling digital experiences for global startups and enterprises over the past 11 years, you know how crucial the web is. | H6: Website Development | I6: Service 1 | O6: DO_NOT_CONTACT | R6: 46233.482
A7: 4 | B7: Open AI | C7: Piyush | D7: piyushbutola07@gmail.com | E7: https://openai.com/ | F7: AI | G7: As OpenAI continues to deploy frontier intelligence tools and API platforms for developers, user-facing digital infrastructure remains central to the ecosystem. | H7: Website Development | I7: Service 1 | J7: 46233.743 | K7: 46233.766 | N7: 46233.766 | O7: FOLLOWUP_1_SENT | P7: 19fb2f77576e8c74 | R7: 46233.766
A8: 5 | B8: Kartik Enterprises | C8: Kartik | D8: kartikdynamisers@gmail.com | E8: https://kartik.com/ | F8: Domain Resale | G8: Managing a diverse portfolio of over 700 domains across finance and tech requires a streamlined digital setup for secure client interactions. | H8: Website Development | I8: Service 1 | J8: 46233.744 | K8: 46233.766 | N8: 46233.766 | O8: FOLLOWUP_1_SENT | P8: 19fb2f94280893c9 | R8: 46233.766
A9: 6 | B9: Blue Bottle Coffee | C9: Alex Carter | D9: forhek496@gmail.com | E9: https://bluebottlecoffee.com | F9: Coffee & Retail | G9: Scaling a direct-to-consumer specialty coffee subscription alongside physical cafe locations requires a seamless digital experience for customers buying brewing tools and beans online. | H9: Website Development | I9: Service 1 | J9: 46233.746 | K9: 46233.766 | N9: 46233.766 | O9: FOLLOWUP_1_SENT | P9: 19fb2fb10436a965 | R9: 46233.766
A10: 7 | B10: Notion | C10: Emma Wilson | D10: anshxname@gmail.com | E10: https://www.notion.so | F10: SaaS | G10: Scaling a platform that combines docs, projects, and AI-powered automation requires a seamless web experience to keep teams connected. | H10: Website Development | I10: Service 1 | J10: 46233.747 | K10: 46233.766 | N10: 46233.766 | O10: FOLLOWUP_1_SENT | P10: 19fb2fcb93f1c035 | R10: 46233.766
A11: 8 | B11: Canva | C11: Liam Brown | D11: pcshado01@gmail.com | E11: https://www.canva.com | F11: Design Software | G11: As an online graphic design platform offering tools from video editors to website builders, expanding your digital touchpoints is central to what you do. | H11: Website Development | I11: Service 1 | J11: 46233.766 | N11: 46233.766 | O11: EMAIL_1_SENT | P11: 19fb315b33a73294 | R11: 46233.766
A12: 9 | B12: Zapier | C12: Sophia Davis | D12: robuxcaedd@gmail.com | E12: https://zapier.com | F12: Automation | G12: As a platform connecting thousands of apps and AI tools, your digital touchpoints play a major role in how teams streamline their operations. | H12: Website Development | I12: Service 1 | J12: 46233.766 | N12: 46233.766 | O12: EMAIL_1_SENT | P12: 19fb315db585d281 | R12: 46233.766
A13: 10 | B13: Figma | C13: Noah Miller | D13: nddunidnuenei@gmail.com | E13: https://www.figma.com | F13: Design Software | G13: As a platform built around collaborative interface design and browser-based product building, the way users experience your web presence is vital. | H13: Website Development | I13: Service 1 | J13: 46233.766 | N13: 46233.766 | O13: EMAIL_1_SENT | P13: 19fb315fc7cc4ed4 | R13: 46233.766
A14: 11 | B14: HubSpot | C14: Olivia Moore | D14: muscelstation@gmail.com | E14: https://www.hubspot.com | F14: CRM | G14: As a platform that unites marketing, sales, and customer service through a smart CRM, your web presence has to keep up with complex operations. | H14: Website Development | I14: Service 1 | J14: 46233.766 | N14: 46233.766 | O14: EMAIL_1_SENT | P14: 19fb31618e44301b | R14: 46233.766
A15: 12 | B15: Webflow | C15: Ethan Taylor | D15: gympremium001@gmail.com | E15: https://webflow.com | F15: Website Builder | G15: As a platform built around visual design and AI-driven tools, managing the intersection of development and marketing on the web is central to your ecosystem. | H15: Website Development | I15: Service 1 | J15: 46233.766 | N15: 46233.766 | O15: EMAIL_1_SENT | P15: 19fb31636d7d76a1 | R15: 46233.766
A16: 13 | B16: Ahrefs | C16: Ava Anderson | D16: kartikdynamisers@gmail.com | E16: https://ahrefs.com | F16: SEO | G16: Building a platform that processes billions of keywords and web pages requires a robust web infrastructure. | H16: Website Development | I16: Service 1 | O16: NEW | R16: 46233.764
A17: 14 | B17: Semrush | C17: Mason Thomas | D17: surajmukul08@gmail.com | E17: https://www.semrush.com | F17: Digital Marketing | G17: As a platform built around SEO and AI search visibility, managing complex web infrastructure is central to delivering your data. | H17: Website Development | I17: Service 1 | J17: 46233.766 | N17: 46233.766 | O17: EMAIL_1_SENT | P17: 19fb31655af8f0b3 | R17: 46233.766
A18: 15 | B18: ClickUp | C18: Isabella Jackson | D18: forstuydy@gmail.com | E18: https://clickup.com | F18: Project Management | G18: Scaling a platform that combines project management, documentation, and AI tools requires a digital experience that clearly showcases complex workflows. | H18: Website Development | I18: Service 1 | J18: 46233.766 | N18: 46233.766 | O18: EMAIL_1_SENT | P18: 19fb31670e8211e7 | R18: 46233.766

Sheet AIResearch
A1: Lead ID | B1: Company | C1: Website | D1: Company Summary | E1: Services Found | F1: Target Audience | G1: Value Proposition | H1: Useful Facts | I1: Researched Confidence | J1: Researched At
A2: 1 | B2: Tiwari Enterprises | C2: https://djgam454.github.io/Portfolio-Website/ | D2: unknown | E2: [] | F2: unknown | G2: unknown | H2: [] | I2: low | J2: 46231.658
A3: 2 | B3: Kant Productions | C3: https://www.dynamisers.com/ | D3: Dynamisers is a digital marketing and web development agency based in Delhi, India, with over 11 years of experience. They provide end-to-end design, development, and marketing solutions to help startups, SMEs, and enterprises build powerful brand identities and scale their digital presence. | E3: ["Digital Marketing","Web Development","Mobile Development","Search Engine Optimization","Social Media Management"] | F3: Startups, SMEs, and enterprises looking to scale their digital presence and brand identity. | G3: Blending intuition with strategy and technical expertise to deliver customized digital marketing and web solutions that scale businesses. | H3: ["The company is based in Delhi, India, with over 11 years of operational experience.","They offer specialized services including graphic design, application development, and pay-per-click advertising.","They cater to multiple industries such as education, healthcare, fashion, and retail."] | I3: high | J3: 46231.659
A4: 3 | B4: Dynamisers | C4: https://www.dynamisers.com/ | D4: Dynamisers is a digital marketing and web development agency based in Delhi, India, with over 11 years of experience providing end-to-end design, development, and marketing solutions for startups, SMEs, and global enterprises. | E4: ["Web Development","Digital Marketing","Search Engine Optimization","Social Media Management","Graphics Designing"] | F4: Startups, SMEs, and enterprises across industries like education, healthcare, fashion, and retail looking to scale their digital presence. | G4: Blending intuition with strategy to translate brand stories into digital experiences that persuade, convert, and scale businesses globally. | H4: ["The company is based in Rajouri Garden, New Delhi, India.","They have over 11 years of industry experience.","They have completed projects across multiple international markets including the UK, EU, USA, UAE, China, and Australia."] | I4: high | J4: 46231.811
A5: 4 | B5: Open AI | C5: https://openai.com/ | D5: OpenAI is an AI research and deployment company that creates artificial intelligence products, tools, and application programming interfaces for individuals, businesses, and developers. | E5: ["ChatGPT","ChatGPT Business","ChatGPT Enterprise","ChatGPT for Education","API Platform"] | F5: Individuals, businesses, developers, and educational institutions | G5: Frontier intelligence that scales with your ambition | H5: ["OpenAI provides research and deployment of artificial intelligence models.","The company offers developer tools including an API platform and Codex.","Products span personal use, business solutions, and educational applications."] | I5: high | J5: 46232.656
A6: 5 | B6: Kartik Enterprises | C6: https://kartik.com/ | D6: Kartik Enterprises operates a premium domain portfolio featuring 737 active domains across categories like finance, tech, Vaastu, and matrimonial services, offering secure transfer options via Escrow.com or GoDaddy. | E6: ["Domain portfolio sales","Secure domain transfer via Escrow.com","Domain brokerage and offers"] | F6: Domain buyers, investors, and businesses looking to acquire premium domain names | G6: Access to a diverse portfolio of 737 active domains with secure escrow transfer and consideration for all offers | H6: ["Manages 737 active domains across 20 categories","Handles transfers securely via Escrow.com or GoDaddy domain push","Contactable via email at kartik@kartik.com or phone/WhatsApp at +1 312 900 2033"] | I6: high | J6: 46232.756
A7: 6 | B7: Blue Bottle Coffee | C7: https://bluebottlecoffee.com | D7: Blue Bottle Coffee is a specialty coffee roaster and retailer offering freshly roasted single-origin coffees, signature blends, matcha, drinkware, and brewing tools through online subscriptions, retail products, and physical cafes. | E7: ["Specialty coffee beans and subscriptions","Craft instant coffee and espresso","Matcha and roasted green tea (Hōjicha)","Coffee brewing tools and equipment","Drinkware and cafe syrups"] | F7: Coffee and matcha enthusiasts seeking specialty, craft-quality beverages and brewing equipment for home or cafe consumption. | G7: Providing meticulously crafted, freshly roasted specialty coffees and seasonal blends designed to elevate everyday coffee rituals. | H7: ["Offers flexible coffee and matcha home subscriptions with customizable delivery schedules.","Operates physical brick-and-mortar cafe locations alongside its e-commerce store.","Provides proprietary items such as Craft Instant Coffee, Craft Matcha, and cafe syrups."] | I7: high | J7: 46233.656
A8: 7 | B8: Notion | C8: https://www.notion.so | D8: Notion provides a connected AI-powered workspace platform that combines docs, knowledge bases, projects, custom agents, and a calendar to help teams and individuals automate tasks, centralize knowledge, and manage workflows. | E8: ["Notion AI tools","Knowledge Base","Projects","Notion Calendar","Custom Agents"] | F8: Teams, startups, small businesses, enterprises, and individuals seeking a unified digital workspace and project management tool. | G8: Bring docs, knowledge bases, projects, and AI-driven automation together into a single platform to streamline workflows and keep teams informed. | H8: ["Over 100 million users worldwide use the platform.","Features built-in AI tools including custom agents, enterprise search, and meeting notes.","Serves multiple team sizes from startups and small businesses to enterprise organizations."] | I8: high | J8: 46233.656
A9: 8 | B9: Canva | C9: https://www.canva.com | D9: Canva is an online visual suite and graphic design platform offering a wide range of tools for creating social media posts, presentations, videos, websites, and print products. | E9: ["Video editor","Photo editor","Presentation maker","Website builder","AI image generator"] | F9: Individuals, small businesses, enterprises, educators, and students looking for visual creation and design tools. | G9: An all-in-one visual suite providing easy-to-use design tools, templates, and AI capabilities for everyone. | H9: ["Offers a comprehensive visual suite including docs, whiteboards, presentations, and social media tools.","Features Canva AI tools like Magic Write, Magic Animate, and Magic Resize.","Provides specific plans tailored for individuals, teams, enterprises, and education."] | I9: high | J9: 46233.656
A10: 9 | B10: Zapier | C10: https://zapier.com | D10: Zapier provides a no-code automation platform that connects thousands of everyday apps, workflows, and AI tools to help businesses streamline operations and build automated systems. | E10: ["Zap workflows","Zapier Tables","Zapier Forms","Zapier Agents","Zapier Chatbots"] | F10: Businesses ranging from startups and small-to-medium businesses to enterprises, including teams across marketing, sales, IT, HR, and customer support. | G10: Automate workflows and connect over 9,000 apps and AI tools without writing code, enabling teams to save time and scale processes. | H10: ["Supports connections across more than 9,000 apps.","Provides enterprise-grade features including SOC 2 and SOC 3 compliance, GDPR compliance, and SAML-based SSO.","Includes built-in tools like Tables and Forms to store data and capture inputs for workflows."] | I10: high | J10: 46233.656
A11: 10 | B11: Figma | C11: https://www.figma.com | D11: Figma is a collaborative interface design tool that enables teams to design, prototype, and build products together in the browser. | E11: ["Design","Prototyping","FigJam collaborative whiteboarding","Design systems","Code generation and handoff"] | F11: Designers, developers, product managers, and cross-functional teams | G11: Bring teams together to build products faster through collaborative design and brainstorming in a single platform. | H11: ["Provides tools for both UI/UX design and team brainstorming via FigJam","Offers features to connect design work with code handoff"] | I11: high | J11: 46233.656
A12: 11 | B12: HubSpot | C12: https://www.hubspot.com | D12: HubSpot offers an all-in-one customer platform featuring marketing, sales, customer service, content management, data management, and billing software powered by a smart CRM and artificial intelligence tools. | E12: ["Marketing Hub","Sales Hub","Service Hub","Content Hub","Smart CRM"] | F12: Go-to-market teams, startups, small businesses, and enterprises looking to unite marketing, sales, and customer service operations. | G12: Unite marketing, sales, and customer service on one agentic customer platform that connects data and tools to make growing a business easier. | H12: ["Offers a Smart CRM that functions as a single source of truth connecting business data.","Includes Agent Hub for building and managing AI agents across the platform.","Provides over 2,000 app integrations with tools like Gmail, Shopify, and Salesforce."] | I12: high | J12: 46233.656
A13: 12 | B13: Webflow | C13: https://webflow.com | D13: Webflow provides an agentic web platform for modern businesses, allowing marketers, designers, developers, and agencies to build, manage, and optimize websites and web experiences visually and with AI tools. | E13: ["Visual web design and page building","Composable CMS and content management","Web hosting and security","Webflow AI and AEO (Answer Engine Optimization)","Webflow MCP (Model Context Protocol) and developer integrations"] | F13: Marketers, designers, developers, agencies, and enterprise businesses | G13: Build websites that drive results by combining design, content management, AI features, and optimization into a single platform without traditional developer bottlenecks. | H13: ["Webflow offers an AEO feature to optimize sites for AI-driven search.","The platform includes a Model Context Protocol (MCP) server for connecting AI agents and IDEs.","Webflow provides a visual-first CMS and hosting environment."] | I13: high | J13: 46233.656
... A16: 15 | B16: ClickUp | C16: https://clickup.com | D16: ClickUp offers a productivity platform that combines project management, documentation, chat, calendars, whiteboards, and AI tools to replace fragmented software and streamline team workflows. | E16: ["Project Management","ClickUp Brain (AI)","Chat","Docs","Whiteboards"] | F16: Teams, departments, and companies across various functions like marketing, product and engineering, IT, HR, and leadership | G16: Software to replace all software, saving money and time by bringing all apps, AI, projects, and chat together with perfect context. | H16: ["Features AI agents and workflows designed to automate tasks across different teams.","Provides a unified workspace featuring time tracking, goals, dashboards, and automated workflows."] | I16: high | J16: 46233.735

Sheet Services
A1: Order | B1: Service | C1: Active
A2: 1 | B2: Website Development | C2: TRUE
A3: 2 | B3: SEO | C3: TRUE
A4: 3 | B4: Google Ads | C4: TRUE

Sheet Templates
A1: Service | B1: Campaign Step | C1: Subject | D1: Plain Text Template | E1: Variant ID | F1: HTML Template | G1: CTA Button Text | H1: CTA URL | I1: Theme | J1: Hero Image | K1: Portfolio Image | L1: Status | M1: Notes
A2: Website Development | B2: EMAIL_1 | C2: A website idea for {{Company}} | D2: Hi {{FirstName}}, {{PersonalisedIntro}} At Dynamisers we build websites that do more than look good — they turn visitors into enquiries. Most businesses we speak to are leaving that on the table. If you're open to it, I'd love to share one quick idea specific to {{Company}} — no cost, no commitment. A few things we focus on: {{Features}} CTA: {{CtaText}} — {{CtaUrl}} Regards, {{SenderName}} {{SenderRole}}, {{CompanyName}} {{ReplyToEmail}} · {{CompanyWebsite}} {{UnsubscribeMessage}} | E2: 1 | F2: {{Header}} {{Hero}} <div style="padding:12px 32px 0;font-size:15px;color:#334155;line-height:1.65;font-family:Arial,Helvetica,sans-serif;">Hi {{FirstName}},</div> <div style="padding:12px 32px 0;font-size:15px;color:#334155;line-height:1.65;font-family:Arial,Helvetica,sans-serif;">{{PersonalisedIntro}}</div> <div style="padding:12px 32px 0;font-size:15px;color:#334155;line-height:1.65;font-family:Arial,Helvetica,sans-serif;">At Dynamisers we build websites that do more than look good — they turn visitors into enquiries. Most businesses we speak to are leaving that on the table.</div> <div style="padding:12px 32px 0;font-size:15px;color:#334155;line-height:1.65;font-family:Arial,Helvetica,sans-serif;">If you're open to it, I'd love to share one quick idea specific to {{Company}} — no cost, no commitment.</div> {{FeatureList}} {{PortfolioShowcase}} {{CtaButton}} {{Divider}} {{SignatureBlock}} {{SocialLinks}} {{Footer}} {{UnsubscribeBlock}} | G2: Reply and let's talk | L2: ACTIVE | M2: Initial outreach — professional intro, variant A
A3: Website Development | B3: EMAIL_1 | C3: Quick question about {{Company}}'s website | D3: Hi {{FirstName}}, {{PersonalisedIntro}} A website usually has one job: turning a visitor into a customer. I help businesses make sure theirs actually does that. Quick question — is {{Website}} getting the results you'd expect from it? A few things we focus on: {{Features}} CTA: {{CtaText}} — {{CtaUrl}} Regards, {{SenderName}} {{SenderRole}}, {{CompanyName}} {{ReplyToEmail}} · {{CompanyWebsite}} {{UnsubscribeMessage}} | E3: 2 | F3: {{Header}} {{Hero}} <div style="padding:12px 32px 0;font-size:15px;color:#334155;line-height:1.65;font-family:Arial,Helvetica,sans-serif;">Hi {{FirstName}},</div> <div style="padding:12px 32px 0;font-size:15px;color:#334155;line-height:1.65;font-family:Arial,Helvetica,sans-serif;">{{PersonalisedIntro}}</div> <div style="padding:12px 32px 0;font-size:15px;color:#334155;line-height:1.65;font-family:Arial,Helvetica,sans-serif;">A website usually has one job: turning a visitor into a customer. I help businesses make sure theirs actually does that.</div> <div style="padding:12px 32px 0;font-size:15px;color:#334155;line-height:1.65;font-family:Arial,Helvetica,sans-serif;">Quick question — is {{Website}} getting the results you'd expect from it?</div> {{FeatureList}} {{PortfolioShowcase}} {{CtaButton}} {{Divider}} {{SignatureBlock}} {{SocialLinks}} {{Footer}} {{UnsubscribeBlock}} | G3: Happy to share ideas | L3: ACTIVE | M3: Initial outreach — professional intro, variant B
A4: Website Development | B4: FOLLOWUP_1 | C4: One more thought about your website | D4: Hi {{FirstName}}, I wanted to add one thought to my earlier email — I know inboxes get full. Improving a website doesn't always mean a redesign. Sometimes it's structure, speed or the first screen a visitor sees. If {{Company}}'s website is generating enquiries, you can ignore this. If not, a 10-minute call is all it takes to find out why. A few things we focus on: {{Features}} CTA: {{CtaText}} — {{CtaUrl}} Regards, {{SenderName}} {{SenderRole}}, {{CompanyName}} {{ReplyToEmail}} · {{CompanyWebsite}} {{UnsubscribeMessage}} | E4: 1 | F4: {{Header}} {{Hero}} <div style="padding:12px 32px 0;font-size:15px;color:#334155;line-height:1.65;font-family:Arial,Helvetica,sans-serif;">Hi {{FirstName}},</div> <div style="padding:12px 32px 0;font-size:15px;color:#334155;line-height:1.65;font-family:Arial,Helvetica,sans-serif;">I wanted to add one thought to my earlier email — I know inboxes get full.</div> <div style="padding:12px 32px 0;font-size:15px;color:#334155;line-height:1.65;font-family:Arial,Helvetica,sans-serif;">Improving a website doesn't always mean a redesign. Sometimes it's structure, speed or the first screen a visitor sees.</div> <div style="padding:12px 32px 0;font-size:15px;color:#334155;line-height:1.65;font-family:Arial,Helvetica,sans-serif;">If {{Company}}'s website is generating enquiries, you can ignore this. If not, a 10-minute call is all it takes to find out why.</div> {{FeatureList}} {{PortfolioShowcase}} {{CtaButton}} {{Divider}} {{SignatureBlock}} {{SocialLinks}} {{Footer}} {{UnsubscribeBlock}} | G4: Open to a quick call? | L4: ACTIVE | M4: Gentle reminder, variant A
A5: Website Development | B5: FOLLOWUP_1 | C5: Re: {{Company}} | D5: Hi {{FirstName}}, Just nudging this back to the top of your inbox. The idea I sent was simple: make {{Website}} work harder for {{Company}} — more enquiries from the same visitors. Worth a look when you have a moment? A few things we focus on: {{Features}} CTA: {{CtaText}} — {{CtaUrl}} Regards, {{SenderName}} {{SenderRole}}, {{CompanyName}} {{ReplyToEmail}} · {{CompanyWebsite}} {{UnsubscribeMessage}} | E5: 2 | F5: {{Header}} {{Hero}} <div style="padding:12px 32px 0;font-size:15px;color:#334155;line-height:1.65;font-family:Arial,Helvetica,sans-serif;">Hi {{FirstName}},</div> <div style="padding:12px 32px 0;font-size:15px;color:#334155;line-height:1.65;font-family:Arial,Helvetica,sans-serif;">Just nudging this back to the top of your inbox.</div> <div style="padding:12px 32px 0;font-size:15px;color:#334155;line-height:1.65;font-family:Arial,Helvetica,sans-serif;">The idea I sent was simple: make {{Website}} work harder for {{Company}} — more enquiries from the same visitors.</div> <div style="padding:12px 32px 0;font-size:15px;color:#334155;line-height:1.65;font-family:Arial,Helvetica,sans-serif;">Worth a look when you have a moment?</div> {{FeatureList}} {{PortfolioShowcase}} {{CtaButton}} {{Divider}} {{SignatureBlock}} {{SocialLinks}} {{Footer}} {{UnsubscribeBlock}} | G5: See what we mean | L5: ACTIVE | M5: Gentle reminder, variant B
A6: Website Development | B6: FOLLOWUP_2 | C6: How we helped a similar business get more enquiries | D6: Hi {{FirstName}}, A quick example of the work we do: one client in a similar space came to us with a website that looked fine but generated almost no enquiries. After a focused rebuild — clearer structure, faster pages, a message that matched their customers — enquiries became a regular part of their week. Happy to share the details if that sounds relevant to {{Company}}. A few things we focus on: {{Features}} CTA: {{CtaText}} — {{CtaUrl}} Regards, {{SenderName}} {{SenderRole}}, {{CompanyName}} {{ReplyToEmail}} · {{CompanyWebsite}} {{UnsubscribeMessage}} | E6: 1 | F6: {{Header}} {{Hero}} <div style="padding:12px 32px 0;font-size:15px;color:#334155;line-height:1.65;font-family:Arial,Helvetica,sans-serif;">Hi {{FirstName}},</div> <div style="padding:12px 32px 0;font-size:15px;color:#334155;line-height:1.65;font-family:Arial,Helvetica,sans-serif;">A quick example of the work we do: one client in a similar space came to us with a website that looked fine but generated almost no enquiries.</div> <div style="padding:12px 32px 0;font-size:15px;color:#334155;line-height:1.65;font-family:Arial,Helvetica,sans-serif;">After a focused rebuild — clearer structure, faster pages, a message that matched their customers — enquiries became a regular part of their week.</div> <div style="padding:12px 32px 0;font-size:15px;color:#334155;line-height:1.65;font-family:Arial,Helvetica,sans-serif;">Happy to share the details if that sounds relevant to {{Company}}.</div> {{FeatureList}} {{PortfolioShowcase}} {{CtaButton}} {{Divider}} {{SignatureBlock}} {{SocialLinks}} {{Footer}} {{UnsubscribeBlock}} | G6: Share the case study | L6: ACTIVE | M6: Case study angle, variant A
A7: Website Development | B7: FOLLOWUP_2 | C7: Proof it works — {{Company}} | D7: Hi {{FirstName}}, Rather than promise what we can do, here's how we work: we look at what your website should be doing for {{Company}}, fix what's in the way, and measure the difference. No long retainers, no jargon — just a website that earns its keep. Our portfolio is here if you'd like to see the kind of work we ship: {{PortfolioUrl}} A few things we focus on: {{Features}} CTA: {{CtaText}} — {{CtaUrl}} Regards, {{SenderName}} {{SenderRole}}, {{CompanyName}} {{ReplyToEmail}} · {{CompanyWebsite}} {{UnsubscribeMessage}} | E7: 2 | F7: {{Header}} {{Hero}} <div style="padding:12px 32px 0;font-size:15px;color:#334155;line-height:1.65;font-family:Arial,Helvetica,sans-serif;">Hi {{FirstName}},</div> <div style="padding:12px 32px 0;font-size:15px;color:#334155;line-height:1.65;font-family:Arial,Helvetica,sans-serif;">Rather than promise what we can do, here's how we work: we look at what your website should be doing for {{Company}}, fix what's in the way, and measure the difference.</div> <div style="padding:12px 32px 0;font-size:15px;color:#334155;line-height:1.65;font-family:Arial,Helvetica,sans-serif;">No long retainers, no jargon — just a website that earns its keep.</div> <div style="padding:12px 32px 0;font-size:15px;color:#334155;line-height:1.65;font-family:Arial,Helvetica,sans-serif;">Our portfolio is here if you'd like to see the kind of work we ship: {{PortfolioUrl}}</div> {{FeatureList}} {{PortfolioShowcase}} {{CtaButton}} {{Divider}} {{SignatureBlock}} {{SocialLinks}} {{Footer}} {{UnsubscribeBlock}} | G7: View our portfolio | L7: ACTIVE | M7: Proof / portfolio angle, variant B
A8: Website Development | B8: FOLLOWUP_3 | C8: Closing the loop with {{Company}} | D8: Hi {{FirstName}}, I'll close the loop here so I don't keep filling your inbox. If improving {{Website}} becomes a priority at {{Company}}, we'd love to help. If it's not the right time, no worries at all — just reply 'not interested' and I won't reach out again. CTA: {{CtaText}} — {{CtaUrl}} Regards, {{SenderName}} {{SenderRole}}, {{CompanyName}} {{ReplyToEmail}} · {{CompanyWebsite}} {{UnsubscribeMessage}} | E8: 1 | F8: {{Header}} {{Hero}} <div style="padding:12px 32px 0;font-size:15px;color:#334155;line-height:1.65;font-family:Arial,Helvetica,sans-serif;">Hi {{FirstName}},</div> <div style="padding:12px 32px 0;font-size:15px;color:#334155;line-height:1.65;font-family:Arial,Helvetica,sans-serif;">I'll close the loop here so I don't keep filling your inbox.</div> <div style="padding:12px 32px 0;font-size:15px;color:#334155;line-height:1.65;font-family:Arial,Helvetica,sans-serif;">If improving {{Website}} becomes a priority at {{Company}}, we'd love to help. If it's not the right time, no worries at all — just reply 'not interested' and I won't reach out again.</div> {{PortfolioShowcase}} {{CtaButton}} {{Divider}} {{SignatureBlock}} {{SocialLinks}} {{Footer}} {{UnsubscribeBlock}} | G8: Keep in touch | L8: ACTIVE | M8: Final follow-up, variant A
A9: Website Development | B9: FOLLOWUP_3 | C9: Last note about your website | D9: Hi {{FirstName}}, This will be my last email on this. One honest point: most businesses we speak to don't need a new website — they need one that actually brings in enquiries. That's the problem we solve. If that ever matters to {{Company}}, my inbox is open. CTA: {{CtaText}} — {{CtaUrl}} Regards, {{SenderName}} {{SenderRole}}, {{CompanyName}} {{ReplyToEmail}} · {{CompanyWebsite}} {{UnsubscribeMessage}} | E9: 2 | F9: {{Header}} {{Hero}} <div style="padding:12px 32px 0;font-size:15px;color:#334155;line-height:1.65;font-family:Arial,Helvetica,sans-serif;">Hi {{FirstName}},</div> <div style="padding:12px 32px 0;font-size:15px;color:#334155;line-height:1.65;font-family:Arial,Helvetica,sans-serif;">This will be my last email on this.</div> <div style="padding:12px 32px 0;font-size:15px;color:#334155;line-height:1.65;font-family:Arial,Helvetica,sans-serif;">One honest point: most businesses we speak to don't need a new website — they need one that actually brings in enquiries. That's the problem we solve.</div> <div style="padding:12px 32px 0;font-size:15px;color:#334155;line-height:1.65;font-family:Arial,Helvetica,sans-serif;">If that ever matters to {{Company}}, my inbox is open.</div> {{PortfolioShowcase}} {{CtaButton}} {{Divider}} {{SignatureBlock}} {{SocialLinks}} {{Footer}} {{UnsubscribeBlock}} | G9: See our work | L9: ACTIVE | M9: Final follow-up, variant B
A10: SEO | B10: EMAIL_1 | C10: An SEO idea for {{Company}} | D10: Hi {{FirstName}}, {{PersonalisedIntro}} At Dynamisers we approach SEO as more than rankings — it's about being found by the right customers at the moment they're looking. I'd like to send you one idea for {{Company}}, based on your industry. Would that be useful? A few things we focus on: {{Features}} CTA: {{CtaText}} — {{CtaUrl}} Regards, {{SenderName}} {{SenderRole}}, {{CompanyName}} {{ReplyToEmail}} · {{CompanyWebsite}} {{UnsubscribeMessage}} | E10: 1 | F10: {{Header}} {{Hero}} <div style="padding:12px 32px 0;font-size:15px;color:#334155;line-height:1.65;font-family:Arial,Helvetica,sans-serif;">Hi {{FirstName}},</div> <div style="padding:12px 32px 0;font-size:15px;color:#334155;line-height:1.65;font-family:Arial,Helvetica,sans-serif;">{{PersonalisedIntro}}</div> <div style="padding:12px 32px 0;font-size:15px;color:#334155;line-height:1.65;font-family:Arial,Helvetica,sans-serif;">At Dynamisers we approach SEO as more than rankings — it's about being found by the right customers at the moment they're looking.</div> <div style="padding:12px 32px 0;font-size:15px;color:#334155;line-height:1.65;font-family:Arial,Helvetica,sans-serif;">I'd like to send you one idea for {{Company}}, based on your industry. Would that be useful?</div> {{FeatureList}} {{PortfolioShowcase}} {{CtaButton}} {{Divider}} {{SignatureBlock}} {{SocialLinks}} {{Footer}} {{UnsubscribeBlock}} | G10: Yes, send it over | L10: ACTIVE | M10: Initial outreach — professional intro, variant A
A11: SEO | B11: EMAIL_1 | C11: {{Company}} in search results | D11: Hi {{FirstName}}, {{PersonalisedIntro}} When someone searches for what {{Company}} offers, do they find you? For most businesses the answer is a mixture of 'sometimes' and 'after three pages'. That gap is exactly what we fix — with work you can see and measure. A few things we focus on: {{Features}} CTA: {{CtaText}} — {{CtaUrl}} Regards, {{SenderName}} {{SenderRole}}, {{CompanyName}} {{ReplyToEmail}} · {{CompanyWebsite}} {{UnsubscribeMessage}} | E11: 2 | F11: {{Header}} {{Hero}} <div style="padding:12px 32px 0;font-size:15px;color:#334155;line-height:1.65;font-family:Arial,Helvetica,sans-serif;">Hi {{FirstName}},</div> <div style="padding:12px 32px 0;font-size:15px;color:#334155;line-height:1.65;font-family:Arial,Helvetica,sans-serif;">{{PersonalisedIntro}}</div> <div style="padding:12px 32px 0;font-size:15px;color:#334155;line-height:1.65;font-family:Arial,Helvetica,sans-serif;">When someone searches for what {{Company}} offers, do they find you? For most businesses the answer is a mixture of 'sometimes' and 'after three pages'.</div> <div style="padding:12px 32px 0;font-size:15px;color:#334155;line-height:1.65;font-family:Arial,Helvetica,sans-serif;">That gap is exactly what we fix — with work you can see and measure.</div> {{FeatureList}} {{PortfolioShowcase}} {{CtaButton}} {{Divider}} {{SignatureBlock}} {{SocialLinks}} {{Footer}} {{UnsubscribeBlock}} | G11: Let's find your gap | L11: ACTIVE | M11: Initial outreach — professional intro, variant B
A12: SEO | B12: FOLLOWUP_1 | C12: Re: your search visibility | D12: Hi {{FirstName}}, Following up on my note about {{Company}}'s search visibility — I know this one's easy to set aside. SEO isn't about chasing rankings for its own sake. It's about showing up when a potential customer is actively looking for what you do. If organic traffic matters to {{Company}}, I can show you exactly where the opportunities are. A few things we focus on: {{Features}} CTA: {{CtaText}} — {{CtaUrl}} Regards, {{SenderName}} {{SenderRole}}, {{CompanyName}} {{ReplyToEmail}} · {{CompanyWebsite}} {{UnsubscribeMessage}} | E12: 1 | F12: {{Header}} {{Hero}} <div style="padding:12px 32px 0;font-size:15px;color:#334155;line-height:1.65;font-family:Arial,Helvetica,sans-serif;">Hi {{FirstName}},</div> <div style="padding:12px 32px 0;font-size:15px;color:#334155;line-height:1.65;font-family:Arial,Helvetica,sans-serif;">Following up on my note about {{Company}}'s search visibility — I know this one's easy to set aside.</div> <div style="padding:12px 32px 0;font-size:15px;color:#334155;line-height:1.65;font-family:Arial,Helvetica,sans-serif;">SEO isn't about chasing rankings for its own sake. It's about showing up when a potential customer is actively looking for what you do.</div> <div style="padding:12px 32px 0;font-size:15px;color:#334155;line-height:1.65;font-family:Arial,Helvetica,sans-serif;">If organic traffic matters to {{Company}}, I can show you exactly where the opportunities are.</div> {{FeatureList}} {{PortfolioShowcase}} {{CtaButton}} {{Divider}} {{SignatureBlock}} {{SocialLinks}} {{Footer}} {{UnsubscribeBlock}} | G12: Show me the opportunities | L12: ACTIVE | M12: Gentle reminder, variant A
A13: SEO | B13: FOLLOWUP_1 | C13: One thing I noticed about {{Company}} | D13: Hi {{FirstName}}, One thing I keep noticing with businesses like {{Company}}: the demand is there, but the website isn't the one capturing it. With a few focused changes, the searches you already appear in can work much harder. Worth 10 minutes to talk through? A few things we focus on: {{Features}} CTA: {{CtaText}} — {{CtaUrl}} Regards, {{SenderName}} {{SenderRole}}, {{CompanyName}} {{ReplyToEmail}} · {{CompanyWebsite}} {{UnsubscribeMessage}} | E13: 2 | F13: {{Header}} {{Hero}} <div style="padding:12px 32px 0;font-size:15px;color:#334155;line-height:1.65;font-family:Arial,Helvetica,sans-serif;">Hi {{FirstName}},</div> <div style="padding:12px 32px 0;font-size:15px;color:#334155;line-height:1.65;font-family:Arial,Helvetica,sans-serif;">One thing I keep noticing with businesses like {{Company}}: the demand is there, but the website isn't the one capturing it.</div> <div style="padding:12px 32px 0;font-size:15px;color:#334155;line-height:1.65;font-family:Arial,Helvetica,sans-serif;">With a few focused changes, the searches you already appear in can work much harder.</div> <div style="padding:12px 32px 0;font-size:15px;color:#334155;line-height:1.65;font-family:Arial,Helvetica,sans-serif;">Worth 10 minutes to talk through?</div> {{FeatureList}} {{PortfolioShowcase}} {{CtaButton}} {{Divider}} {{SignatureBlock}} {{SocialLinks}} {{Footer}} {{UnsubscribeBlock}} | G13: Let's talk it through | L13: ACTIVE | M13: Gentle reminder, variant B
... A25: Google Ads | B25: FOLLOWUP_3 | C25: Closing the loop with {{Company}} | D25: Hi {{FirstName}}, Closing the loop — thanks for reading this far. We help businesses turn Google Ads from a cost centre into a channel they can trust. When paid search makes sense for {{Company}}, that's our pitch. All the best, and take care. CTA: {{CtaText}} — {{CtaUrl}} Regards, {{SenderName}} {{SenderRole}}, {{CompanyName}} {{ReplyToEmail}} · {{CompanyWebsite}} {{UnsubscribeMessage}} | E25: 2 | F25: {{Header}} {{Hero}} <div style="padding:12px 32px 0;font-size:15px;color:#334155;line-height:1.65;font-family:Arial,Helvetica,sans-serif;">Hi {{FirstName}},</div> <div style="padding:12px 32px 0;font-size:15px;color:#334155;line-height:1.65;font-family:Arial,Helvetica,sans-serif;">Closing the loop — thanks for reading this far.</div> <div style="padding:12px 32px 0;font-size:15px;color:#334155;line-height:1.65;font-family:Arial,Helvetica,sans-serif;">We help businesses turn Google Ads from a cost centre into a channel they can trust. When paid search makes sense for {{Company}}, that's our pitch.</div> <div style="padding:12px 32px 0;font-size:15px;color:#334155;line-height:1.65;font-family:Arial,Helvetica,sans-serif;">All the best, and take care.</div> {{PortfolioShowcase}} {{CtaButton}} {{Divider}} {{SignatureBlock}} {{SocialLinks}} {{Footer}} {{UnsubscribeBlock}} | G25: See our work | L25: ACTIVE | M25: Final follow-up, variant B

Sheet Themes
A1: Theme | B1: Accent | C1: Accent Dark | D1: Hero Background | E1: Hero Text | F1: Hero Subtext | G1: Button Background | H1: Button Text | I1: Card Border | J1: Status
A2: website | B2: #2563EB | C2: #1D4ED8 | D2: #2563EB | E2: #FFFFFF | F2: #DBEAFE | G2: #2563EB | H2: #FFFFFF | I2: #E2E8F0 | J2: Active
A3: seo | B3: #059669 | C3: #047857 | D3: #059669 | E3: #FFFFFF | F3: #D1FAE5 | G3: #059669 | H3: #FFFFFF | I3: #E2E8F0 | J3: Active
A4: google-ads | B4: #EA580C | C4: #C2410C | D4: #EA580C | E4: #FFFFFF | F4: #FFEDD5 | G4: #EA580C | H4: #FFFFFF | I4: #E2E8F0 | J4: Active

Sheet Config
A1: A — Setting | B1: B — Value
A2: AUTOMATION_ENABLED | B2: TRUE
A3: DAILY_LIMIT | B3: 35
A4: FOLLOWUP_1_MINUTES | B4: 0
A5: FOLLOWUP_2_MINUTES | B5: 0
A6: FOLLOWUP_3_MINUTES | B6: 0
A7: TEST_MODE | B7: FALSE
A8: TEST_EMAIL | B8: divyantiwariuni4@gmail.com
A9: NEXT_SERVICE_MINUTES | B9: 0
A10: FAST_TEST_MODE | B10: TRUE
A11: TIMEZONE | B11: Europe/London
A12: WORKING_DAYS | B12: MON,TUE,WED,THU,FRI
A13: SEND_START_HOUR | B13: 9
A14: SEND_END_HOUR | B14: 17
A15: FOLLOWUP_1_DAYS | B15: 2
A16: FOLLOWUP_2_DAYS | B16: 5
A17: FOLLOWUP_3_DAYS | B17: 7
A18: NEXT_SERVICE_DAYS | B18: 1
A19: PREVIEW_MODE | B19: TRUE
A20: SENDER_NAME | B20: Divyan Tiwari
A21: REPLY_TO_EMAIL | B21: djgamer454@gmail.com
A22: EMAIL_SIGNATURE | B22: Regards, {{SenderName}} {{SenderRole}}, {{CompanyName}}
A23: COMPANY_NAME | B23: Dynamiser Solutions
A24: COMPANY_WEBSITE | B24: https://dynamisers.com
A25: COMPANY_EMAIL | B25: djgamer454@gmail.com
A26: COMPANY_PHONE
A27: COMPANY_ADDRESS
A28: SOCIAL_LINKEDIN | B28: https://www.linkedin.com/company/dynamiser-solutions
A29: SOCIAL_TWITTER
A30: SOCIAL_GITHUB
A31: PORTFOLIO_URL | B31: https://djgam454.github.io/Portfolio-Website/
A32: DEFAULT_CTA_TEXT | B32: Reply to this email
A33: DEFAULT_CTA_URL
A34: UNSUBSCRIBE_MESSAGE | B34: If this isn't relevant right now, just reply "not interested" and I won't contact you again.
A35: SENDER_ROLE | B35: Business Development
A36: HERO_TITLE | B36: Helping {{Company}} grow
A37: HERO_SUBTITLE | B37: A short note from {{SenderName}} at {{CompanyName}}
A38: SERVICE_BENEFIT_WEBSITE_DEVELOPMENT | B38: a website that builds trust and turns visitors into enquiries
A39: SERVICE_BENEFIT_SEO | B39: visibility for the searches that actually matter to your business
A40: SERVICE_BENEFIT_GOOGLE_ADS | B40: paid visibility in front of customers already looking for what you offer
...

Sheet Preview
A1: Generated At | B1: Lead ID | C1: Email | D1: Company | E1: Service | F1: Step | G1: Subject | H1: Variant ID | I1: Plain Text Preview | J1: HTML Preview
A2: 46233.482 | B2: 3 | C2: dynamisers@gmail.com | D2: Dynamisers | E2: Website Development | F2: EMAIL_1 | G2: SUBJECT: A website idea for Dynamisers BODY: Hi Sudipti, As an agency scaling digital experiences for global startups and enterprises over the past 11 years, you know how crucial the web is. At Dynamisers, we look at a website as more than an online presence — it should communicate your value clearly, guide the right visitors and turn interest into meaningful enquiries. Having built 700+ websites, our approach brings together design, responsive development, performance, SEO-readiness and conversion-focused user journeys. For Dynamisers, we'd be happy to identify a few practical opportunities across the visitor experience and the path from first visit to enquiry — without assuming a complete rebuild is necessary. Would it be useful if I sent over a few initial ideas? Regards, Divyan Tiwari, Dynamiser Solutions

Sheet ActivityLog
A1: Timestamp | B1: Lead ID | C1: Email | D1: Action | E1: Campaign | F1: Service | G1: Status | H1: Gmail Message ID | I1: Gmail Thread ID | J1: Result | K1: Error
A2: 46230.616 | B2: 1 | C2: divyantiwariuni4@gmail.com | D2: FOLLOWUP_1 | F2: Website Development | G2: FOLLOWUP_1_SENT | I2: 19fa2dbadfc06a6e | J2: SUCCESS
A3: 46230.623 | B3: 1 | C3: divyantiwariuni4@gmail.com | D3: EMAIL_1 | E3: Service 1 | F3: Website Development | G3: EMAIL_1_SENT | I3: 19fa2e602fed7ab4 | J3: SUCCESS
A4: 46230.629 | B4: 1 | C4: divyantiwariuni4@gmail.com | D4: FOLLOWUP_1 | F4: Website Development | G4: FOLLOWUP_1_SENT | I4: 19fa2e602fed7ab4 | J4: SUCCESS
A5: 46230.631 | B5: 1 | C5: divyantiwariuni4@gmail.com | D5: FOLLOWUP_2 | F5: Website Development | G5: FOLLOWUP_2_SENT | I5: 19fa2e602fed7ab4 | J5: SUCCESS
A6: 46230.634 | B6: 1 | C6: divyantiwariuni4@gmail.com | D6: FOLLOWUP_3 | F6: Website Development | G6: FOLLOWUP_3_SENT | I6: 19fa2e602fed7ab4 | J6: SUCCESS
A7: 46230.636 | B7: 1 | C7: divyantiwariuni4@gmail.com | D7: EMAIL_1 | E7: Service 1 | F7: Website Development | G7: EMAIL_1_SENT | I7: 19fa2f79e31038b6 | J7: SUCCESS
A8: 46230.649 | B8: 1 | C8: divyantiwariuni4@gmail.com | D8: EMAIL_1 | E8: Service 1 | F8: Website Development | G8: EMAIL_1_SENT | I8: 19fa308a1478c40a | J8: SUCCESS
A9: 46230.649 | B9: 2 | C9: aryandivyan@gmail.com | D9: EMAIL_1 | E9: Service 1 | F9: Website Development | G9: EMAIL_1_SENT | I9: 19fa308acd78363f | J9: SUCCESS
A10: 46230.653 | B10: 1 | C10: divyantiwariuni4@gmail.com | D10: EMAIL_1 | E10: Service 1 | F10: Website Development | G10: EMAIL_1_SENT | I10: 19fa30e6ce592466 | J10: SUCCESS
A11: 46230.654 | B11: 1 | C11: divyantiwariuni4@gmail.com | D11: FOLLOWUP_1 | F11: Website Development | G11: FOLLOWUP_1_SENT | I11: 19fa30e6ce592466 | J11: SUCCESS
A12: 46230.656 | B12: 1 | C12: divyantiwariuni4@gmail.com | D12: FOLLOWUP_2 | F12: Website Development | G12: FOLLOWUP_2_SENT | I12: 19fa30e6ce592466 | J12: SUCCESS
A13: 46230.695 | B13: 1 | C13: divyantiwariuni4@gmail.com | D13: CAMPAIGN_NO_REPLY | F13: Website Development | G13: NOT_INTERESTED_SERVICE_1 | I13: 19fa30e6ce592466 | J13: SUCCESS
A14: 46230.695 | B14: 1 | C14: divyantiwariuni4@gmail.com | D14: CAMPAIGN_STARTED | E14: Service 3 | F14: Google Ads | G14: NEW | J14: SUCCESS
A15: 46230.697 | B15: 1 | C15: divyantiwariuni4@gmail.com | D15: EMAIL_1 | E15: Service 3 | F15: Google Ads | G15: EMAIL_1_SENT | I15: 19fa34735e657623 | J15: SUCCESS
A16: 46230.698 | B16: 1 | C16: divyantiwariuni4@gmail.com | D16: CAMPAIGN_NO_REPLY | F16: Google Ads | G16: NOT_INTERESTED_SERVICE_3 | I16: 19fa34735e657623 | J16: SUCCESS
A17: 46230.698 | B17: 1 | C17: divyantiwariuni4@gmail.com | D17: ALL_CAMPAIGNS_COMPLETED | F17: Google Ads | G17: COMPLETED | I17: 19fa34735e657623 | J17: SUCCESS
A18: 46230.703 | B18: 1 | C18: divyantiwariuni4@gmail.com | D18: CAMPAIGN_NO_REPLY | F18: Website Development | G18: NOT_INTERESTED_SERVICE_1 | I18: 19fa34735e657623 | J18: SUCCESS
A19: 46230.703 | B19: 1 | C19: divyantiwariuni4@gmail.com | D19: CAMPAIGN_STARTED | E19: Service 2 | F19: Google Ads | G19: NEW | J19: SUCCESS
A20: 46230.704 | B20: 1 | C20: divyantiwariuni4@gmail.com | D20: EMAIL_1 | E20: Service 2 | F20: Google Ads | G20: EMAIL_1_SENT | I20: 19fa35140cbb0d37 | J20: SUCCESS
A21: 46230.719 | B21: 1 | C21: divyantiwariuni4@gmail.com | D21: EMAIL_1 | E21: Service 1 | F21: Website Development | G21: EMAIL_1_SENT | I21: 19fa364e663891ee | J21: SUCCESS
A22: 46230.74 | B22: 1 | C22: divyantiwariuni4@gmail.com | D22: FOLLOWUP_1 | F22: Website Development | G22: FOLLOWUP_1_SENT | I22: 19fa364e663891ee | J22: SUCCESS
A23: 46230.753 | B23: 1 | C23: divyantiwariuni4@gmail.com | D23: FOLLOWUP_2 | F23: Website Development | G23: FOLLOWUP_2_SENT | I23: 19fa364e663891ee | J23: SUCCESS
A24: 46230.753 | B24: 2 | C24: aryandivyan@gmail.com | D24: EMAIL_1 | E24: Service 1 | F24: Website Development | G24: EMAIL_1_SENT | I24: 19fa3921472d02ef | J24: SUCCESS
A25: 46230.76 | B25: 1 | C25: divyantiwariuni4@gmail.com | D25: FOLLOWUP_3 | F25: Website Development | G25: FOLLOWUP_3_SENT | I25: 19fa364e663891ee | J25: SUCCESS
A26: 46230.76 | B26: 2 | C26: aryandivyan@gmail.com | D26: FOLLOWUP_1 | F26: Website Development | G26: FOLLOWUP_1_SENT | I26: 19fa3921472d02ef | J26: SUCCESS
A27: 46230.76 | B27: 999 | C27: this-is-not-an-email | D27: EMAIL_VALIDATION_FAILED | E27: Service 1 | F27: Website Development | G27: INVALID | J27: FAILED | K27: Invalid email format
A28: 46230.784 | B28: 1 | C28: divyantiwariuni4@gmail.com | D28: EMAIL_1 | E28: Service 1 | F28: Website Development | G28: EMAIL_1_SENT | I28: 19fa3baa2fc4c7c9 | J28: SUCCESS
A29: 46230.784 | B29: 2 | C29: aryandivyan@gmail.com | D29: EMAIL_1 | E29: Service 1 | F29: Website Development | G29: EMAIL_1_SENT | I29: 19fa3bab02072fb2 | J29: SUCCESS
A30: 46230.784 | B30: 999 | C30: this-is-not-an-email | D30: EMAIL_VALIDATION_FAILED | E30: Service 1 | F30: Website Development | G30: INVALID | J30: FAILED | K30: Invalid email format
A31: 46230.79 | B31: 1 | C31: divyantiwariuni4@gmail.com | D31: FOLLOWUP_1 | F31: Website Development | G31: FOLLOWUP_1_SENT | I31: 19fa3baa2fc4c7c9 | J31: SUCCESS
A32: 46230.79 | B32: 2 | C32: aryandivyan@gmail.com | D32: FOLLOWUP_1 | F32: Website Development | G32: FOLLOWUP_1_SENT | I32: 19fa3bab02072fb2 | J32: SUCCESS
A33: 46231.461 | B33: 1 | C33: divyantiwariuni4@gmail.com | D33: FOLLOWUP_THREAD_MISSING | F33: Website Development | G33: FOLLOWUP_1_SENT | J33: FAILED | K33: Gmail Thread ID missing
A34: 46231.461 | B34: 999 | C34: this-is-not-an-email | D34: EMAIL_VALIDATION_FAILED | E34: Service 1 | F34: Website Development | G34: INVALID | J34: FAILED | K34: Invalid email format
A35: 46231.461 | B35: 998 | C35: nonexistent@your-test-domain.example | D35: EMAIL_1 | E35: Service 1 | F35: Website Development | G35: EMAIL_1_SENT | I35: 19fa737196c16e79 | J35: SUCCESS
A36: 46231.472 | B36: 998 | C36: nonexistent@your-test-domain.example | D36: EMAIL_BOUNCED | E36: Service 1 | F36: Website Development | G36: INVALID | I36: 19fa737196c16e79 | J36: FAILED | K36: Delivery failure / bounced email
A37: 46231.473 | B37: 1 | C37: divyantiwariuni4@gmail.com | D37: EMAIL_1 | E37: Service 1 | F37: Website Development | G37: EMAIL_1_SENT | I37: 19fa7464eeea3206 | J37: SUCCESS
A38: 46231.473 | B38: 1 | C38: divyantiwariuni4@gmail.com | D38: FOLLOWUP_1 | F38: Website Development | G38: FOLLOWUP_1_SENT | I38: 19fa7464eeea3206 | J38: SUCCESS
A39: 46231.473 | B39: 1 | C39: divyantiwariuni4@gmail.com | D39: FOLLOWUP_2 | F39: Website Development | G39: FOLLOWUP_2_SENT | I39: 19fa7464eeea3206 | J39: SUCCESS
A40: 46231.473 | B40: 1 | C40: divyantiwariuni4@gmail.com | D40: FOLLOWUP_3 | F40: Website Development | G40: FOLLOWUP_3_SENT | I40: 19fa7464eeea3206 | J40: SUCCESS
...

Sheet AIConfig
A1: A — Setting | B1: B — Value
A2: AI_ENABLED | B2: TRUE
A3: AI_MODEL | B3: gemini-3.5-flash-lite
A4: MAX_INTRO_WORDS | B4: 35
A5: TEMPERATURE | B5: 0.4
A6: AI_RPM_LIMIT | B6: 15

Sheet Dashboard
A1: AI Cold Email Automation
A3: Campaign performance, pipeline health and automation activity
A5: SYSTEM STATUS
A6: Automation | B6: ON | C6: Preview Mode | D6: ON | E6: Test Mode | F6: OFF | G6: Fast Test | H6: ON | I6: Daily Usage | J6: =(COUNTIFS(ActivityLog!A2:A1000,">="&TODAY(),ActivityLog!A2:A1000,"<"&TODAY()+1,ActivityLog!J2:J1000,"SUCCESS",ActivityLog!D2:D1000,"EMAIL_1")+COUNTIFS(ActivityLog!A2:A1000,">="&TODAY(),ActivityLog!A2:A1000,"<"&TODAY()+1,ActivityLog!J2:J1000,"SUCCESS",ActivityLog!D2:D1000,"FOLLOWUP_1")+COUNTIFS(ActivityLog!A2:A1000,">="&TODAY(),ActivityLog!A2:A1000,"<"&TODAY()+1,ActivityLog!J2:J1000,"SUCCESS",ActivityLog!D2:D1000,"FOLLOWUP_2")+COUNTIFS(ActivityLog!A2:A1000,">="&TODAY(),ActivityLog!A2:A1000,"<"&TODAY()+1,ActivityLog!J2:J1000,"SUCCESS",ActivityLog!D2:D1000,"FOLLOWUP_3"))&" / 50"
A8: CAMPAIGN OVERVIEW
A9: Total Leads | C9: Active Leads | E9: Emails Sent | G9: Replies | I9: Reply Rate
A10: =COUNTIF(Leads!D2:D1000,"<>") | C10: =COUNTIFS(Leads!D2:D1000,"<>",Leads!O2:O1000,"<>COMPLETED",Leads!O2:O1000,"<>INVALID",Leads!O2:O1000,"<>DO_NOT_CONTACT",Leads!O2:O1000,"<>REPLIED") | E10: =COUNTIFS(ActivityLog!J2:J1000,"SUCCESS",ActivityLog!D2:D1000,"EMAIL_1")+COUNTIFS(ActivityLog!J2:J1000,"SUCCESS",ActivityLog!D2:D1000,"FOLLOWUP_1")+COUNTIFS(ActivityLog!J2:J1000,"SUCCESS",ActivityLog!D2:D1000,"FOLLOWUP_2")+COUNTIFS(ActivityLog!J2:J1000,"SUCCESS",ActivityLog!D2:D1000,"FOLLOWUP_3") | G10: =COUNTIF(Leads!O2:O1000,"REPLIED") | I10: =IFERROR(COUNTIF(Leads!O2:O1000,"REPLIED")/COUNTIF(Leads!D2:D1000,"<>"),0)
A12: New Leads | C12: Completed | E12: Invalid / Bounced | G12: Do Not Contact | I12: Failed Actions
A13: =COUNTIF(Leads!O2:O1000,"NEW") | C13: =COUNTIF(Leads!O2:O1000,"COMPLETED") | E13: =COUNTIF(Leads!O2:O1000,"INVALID") | G13: =COUNTIF(Leads!O2:O1000,"DO_NOT_CONTACT") | I13: =COUNTIF(ActivityLog!J2:J1000,"FAILED")
A15: SERVICE PERFORMANCE | H15: CAMPAIGN PIPELINE
A16: Service | B16: Current Leads | C16: Campaigns Started | D16: Replies | E16: Service Completed | F16: Reply Rate | H16: Stage | I16: Leads
A17: Website Development | B17: =COUNTIFS(Leads!H2:H1000,"Website Development",Leads!O2:O1000,"<>COMPLETED",Leads!O2:O1000,"<>INVALID",Leads!O2:O1000,"<>DO_NOT_CONTACT",Leads!O2:O1000,"<>REPLIED") | C17: =COUNTIFS(ActivityLog!F2:F1000,"Website Development",ActivityLog!D2:D1000,"EMAIL_1",ActivityLog!J2:J1000,"SUCCESS") | D17: =COUNTIFS(Leads!H2:H1000,"Website Development",Leads!O2:O1000,"REPLIED") | E17: =COUNTIF(Leads!O2:O1000,"NOT_INTERESTED_SERVICE_1") | F17: =IFERROR(D17/B17,0) | H17: NEW | I17: =COUNTIF(Leads!O2:O1000,"NEW")
A18: SEO | B18: =COUNTIFS(Leads!H2:H1000,"SEO",Leads!O2:O1000,"<>COMPLETED",Leads!O2:O1000,"<>INVALID",Leads!O2:O1000,"<>DO_NOT_CONTACT",Leads!O2:O1000,"<>REPLIED") | C18: =COUNTIFS(ActivityLog!F2:F1000,"SEO",ActivityLog!D2:D1000,"EMAIL_1",ActivityLog!J2:J1000,"SUCCESS") | D18: =COUNTIFS(Leads!H2:H1000,"SEO",Leads!O2:O1000,"REPLIED") | E18: =COUNTIF(Leads!O2:O1000,"NOT_INTERESTED_SERVICE_2") | F18: =IFERROR(D18/B18,0) | H18: Email 1 Sent | I18: =COUNTIF(Leads!O2:O1000,"EMAIL_1_SENT")
A19: Google Ads | B19: =COUNTIFS(Leads!H2:H1000,"Google Ads",Leads!O2:O1000,"<>COMPLETED",Leads!O2:O1000,"<>INVALID",Leads!O2:O1000,"<>DO_NOT_CONTACT",Leads!O2:O1000,"<>REPLIED") | C19: =COUNTIFS(ActivityLog!F2:F1000,"Google Ads",ActivityLog!D2:D1000,"EMAIL_1",ActivityLog!J2:J1000,"SUCCESS") | D19: =COUNTIFS(Leads!H2:H1000,"Google Ads",Leads!O2:O1000,"REPLIED") | E19: =COUNTIF(Leads!O2:O1000,"NOT_INTERESTED_SERVICE_3") | F19: =IFERROR(D19/B19,0) | H19: Follow-up 1 | I19: =COUNTIF(Leads!O2:O1000,"FOLLOWUP_1_SENT")
H20: Follow-up 2 | I20: =COUNTIF(Leads!O2:O1000,"FOLLOWUP_2_SENT")
H21: Follow-up 3 | I21: =COUNTIF(Leads!O2:O1000,"FOLLOWUP_3_SENT")
A22: DELIVERY OVERVIEW | H22: Replied | I22: =COUNTIF(Leads!O2:O1000,"REPLIED")
A23: Sent Today | B23: Sent This Week | C23: Daily Remaining | D23: Follow-ups Due | E23: Daily Limit | F23: Utilisation | H23: Completed | I23: =COUNTIF(Leads!O2:O1000,"COMPLETED")
A24: =SUMPRODUCT(--(ActivityLog!A2:A1000>=TODAY()),--(ActivityLog!A2:A1000<TODAY()+1),--(ActivityLog!J2:J1000="SUCCESS"),--(((ActivityLog!D2:D1000="EMAIL_1")+(ActivityLog!D2:D1000="FOLLOWUP_1")+(ActivityLog!D2:D1000="FOLLOWUP_2")+(ActivityLog!D2:D1000="FOLLOWUP_3"))>0)) | B24: =SUMPRODUCT(--(ActivityLog!A2:A1000>=TODAY()-WEEKDAY(TODAY(),2)+1),--(ActivityLog!A2:A1000<TODAY()+1),--(ActivityLog!J2:J1000="SUCCESS"),--(((ActivityLog!D2:D1000="EMAIL_1")+(ActivityLog!D2:D1000="FOLLOWUP_1")+(ActivityLog!D2:D1000="FOLLOWUP_2")+(ActivityLog!D2:D1000="FOLLOWUP_3"))>0)) | C24: =MAX(0,50-A24) | D24: - | E24: =Config!B3 | F24: =IFERROR(A24/E24,0)
A26: RECENT ACTIVITY
A27: Timestamp | B27: Email | C27: Action | D27: Campaign | E27: Service | F27: Status | G27: Result
A28: =IFERROR(__xludf.DUMMYFUNCTION("QUERY(ActivityLog!A2:K1000,""select A,C,D,E,F,G,J where A is not null order by A desc limit 10"",0)"),46233.76646680555) | B28: =IFERROR(__xludf.DUMMYFUNCTION("""COMPUTED_VALUE"""),"forstuydy@gmail.com") | C28: =IFERROR(__xludf.DUMMYFUNCTION("""COMPUTED_VALUE"""),"EMAIL_1") | D28: =IFERROR(__xludf.DUMMYFUNCTION("""COMPUTED_VALUE"""),"Service 1") | E28: =IFERROR(__xludf.DUMMYFUNCTION("""COMPUTED_VALUE"""),"Website Development") | F28: =IFERROR(__xludf.DUMMYFUNCTION("""COMPUTED_VALUE"""),"EMAIL_1_SENT") | G28: =IFERROR(__xludf.DUMMYFUNCTION("""COMPUTED_VALUE"""),"SUCCESS")
A29: =IFERROR(__xludf.DUMMYFUNCTION("""COMPUTED_VALUE"""),46233.76638380787) | B29: =IFERROR(__xludf.DUMMYFUNCTION("""COMPUTED_VALUE"""),"surajmukul08@gmail.com") | C29: =IFERROR(__xludf.DUMMYFUNCTION("""COMPUTED_VALUE"""),"EMAIL_1") | D29: =IFERROR(__xludf.DUMMYFUNCTION("""COMPUTED_VALUE"""),"Service 1") | E29: =IFERROR(__xludf.DUMMYFUNCTION("""COMPUTED_VALUE"""),"Website Development") | F29: =IFERROR(__xludf.DUMMYFUNCTION("""COMPUTED_VALUE"""),"EMAIL_1_SENT") | G29: =IFERROR(__xludf.DUMMYFUNCTION("""COMPUTED_VALUE"""),"SUCCESS")
A30: =IFERROR(__xludf.DUMMYFUNCTION("""COMPUTED_VALUE"""),46233.766294270834) | B30: =IFERROR(__xludf.DUMMYFUNCTION("""COMPUTED_VALUE"""),"gympremium001@gmail.com") | C30: =IFERROR(__xludf.DUMMYFUNCTION("""COMPUTED_VALUE"""),"EMAIL_1") | D30: =IFERROR(__xludf.DUMMYFUNCTION("""COMPUTED_VALUE"""),"Service 1") | E30: =IFERROR(__xludf.DUMMYFUNCTION("""COMPUTED_VALUE"""),"Website Development") | F30: =IFERROR(__xludf.DUMMYFUNCTION("""COMPUTED_VALUE"""),"EMAIL_1_SENT") | G30: =IFERROR(__xludf.DUMMYFUNCTION("""COMPUTED_VALUE"""),"SUCCESS")
A31: =IFERROR(__xludf.DUMMYFUNCTION("""COMPUTED_VALUE"""),46233.76620121528) | B31: =IFERROR(__xludf.DUMMYFUNCTION("""COMPUTED_VALUE"""),"muscelstation@gmail.com") | C31: =IFERROR(__xludf.DUMMYFUNCTION("""COMPUTED_VALUE"""),"EMAIL_1") | D31: =IFERROR(__xludf.DUMMYFUNCTION("""COMPUTED_VALUE"""),"Service 1") | E31: =IFERROR(__xludf.DUMMYFUNCTION("""COMPUTED_VALUE"""),"Website Development") | F31: =IFERROR(__xludf.DUMMYFUNCTION("""COMPUTED_VALUE"""),"EMAIL_1_SENT") | G31: =IFERROR(__xludf.DUMMYFUNCTION("""COMPUTED_VALUE"""),"SUCCESS")
A32: =IFERROR(__xludf.DUMMYFUNCTION("""COMPUTED_VALUE"""),46233.76612061342) | B32: =IFERROR(__xludf.DUMMYFUNCTION("""COMPUTED_VALUE"""),"nddunidnuenei@gmail.com") | C32: =IFERROR(__xludf.DUMMYFUNCTION("""COMPUTED_VALUE"""),"EMAIL_1") | D32: =IFERROR(__xludf.DUMMYFUNCTION("""COMPUTED_VALUE"""),"Service 1") | E32: =IFERROR(__xludf.DUMMYFUNCTION("""COMPUTED_VALUE"""),"Website Development") | F32: =IFERROR(__xludf.DUMMYFUNCTION("""COMPUTED_VALUE"""),"EMAIL_1_SENT") | G32: =IFERROR(__xludf.DUMMYFUNCTION("""COMPUTED_VALUE"""),"SUCCESS")
A33: =IFERROR(__xludf.DUMMYFUNCTION("""COMPUTED_VALUE"""),46233.76602753473) | B33: =IFERROR(__xludf.DUMMYFUNCTION("""COMPUTED_VALUE"""),"robuxcaedd@gmail.com") | C33: =IFERROR(__xludf.DUMMYFUNCTION("""COMPUTED_VALUE"""),"EMAIL_1") | D33: =IFERROR(__xludf.DUMMYFUNCTION("""COMPUTED_VALUE"""),"Service 1") | E33: =IFERROR(__xludf.DUMMYFUNCTION("""COMPUTED_VALUE"""),"Website Development") | F33: =IFERROR(__xludf.DUMMYFUNCTION("""COMPUTED_VALUE"""),"EMAIL_1_SENT") | G33: =IFERROR(__xludf.DUMMYFUNCTION("""COMPUTED_VALUE"""),"SUCCESS")
A34: =IFERROR(__xludf.DUMMYFUNCTION("""COMPUTED_VALUE"""),46233.76590712963) | B34: =IFERROR(__xludf.DUMMYFUNCTION("""COMPUTED_VALUE"""),"pcshado01@gmail.com") | C34: =IFERROR(__xludf.DUMMYFUNCTION("""COMPUTED_VALUE"""),"EMAIL_1") | D34: =IFERROR(__xludf.DUMMYFUNCTION("""COMPUTED_VALUE"""),"Service 1") | E34: =IFERROR(__xludf.DUMMYFUNCTION("""COMPUTED_VALUE"""),"Website Development") | F34: =IFERROR(__xludf.DUMMYFUNCTION("""COMPUTED_VALUE"""),"EMAIL_1_SENT") | G34: =IFERROR(__xludf.DUMMYFUNCTION("""COMPUTED_VALUE"""),"SUCCESS")
A35: =IFERROR(__xludf.DUMMYFUNCTION("""COMPUTED_VALUE"""),46233.76584240741) | B35: =IFERROR(__xludf.DUMMYFUNCTION("""COMPUTED_VALUE"""),"anshxname@gmail.com") | C35: =IFERROR(__xludf.DUMMYFUNCTION("""COMPUTED_VALUE"""),"FOLLOWUP_1") | D35: =IFERROR(__xludf.DUMMYFUNCTION("""COMPUTED_VALUE"""),"Service 1") | E35: =IFERROR(__xludf.DUMMYFUNCTION("""COMPUTED_VALUE"""),"Website Development") | F35: =IFERROR(__xludf.DUMMYFUNCTION("""COMPUTED_VALUE"""),"FOLLOWUP_1_SENT") | G35: =IFERROR(__xludf.DUMMYFUNCTION("""COMPUTED_VALUE"""),"SUCCESS")
A36: =IFERROR(__xludf.DUMMYFUNCTION("""COMPUTED_VALUE"""),46233.76577886574) | B36: =IFERROR(__xludf.DUMMYFUNCTION("""COMPUTED_VALUE"""),"forhek496@gmail.com") | C36: =IFERROR(__xludf.DUMMYFUNCTION("""COMPUTED_VALUE"""),"FOLLOWUP_1") | D36: =IFERROR(__xludf.DUMMYFUNCTION("""COMPUTED_VALUE"""),"Service 1") | E36: =IFERROR(__xludf.DUMMYFUNCTION("""COMPUTED_VALUE"""),"Website Development") | F36: =IFERROR(__xludf.DUMMYFUNCTION("""COMPUTED_VALUE"""),"FOLLOWUP_1_SENT") | G36: =IFERROR(__xludf.DUMMYFUNCTION("""COMPUTED_VALUE"""),"SUCCESS")
A37: =IFERROR(__xludf.DUMMYFUNCTION("""COMPUTED_VALUE"""),46233.765712465276) | B37: =IFERROR(__xludf.DUMMYFUNCTION("""COMPUTED_VALUE"""),"kartikdynamisers@gmail.com") | C37: =IFERROR(__xludf.DUMMYFUNCTION("""COMPUTED_VALUE"""),"FOLLOWUP_1") | D37: =IFERROR(__xludf.DUMMYFUNCTION("""COMPUTED_VALUE"""),"Service 1") | E37: =IFERROR(__xludf.DUMMYFUNCTION("""COMPUTED_VALUE"""),"Website Development") | F37: =IFERROR(__xludf.DUMMYFUNCTION("""COMPUTED_VALUE"""),"FOLLOWUP_1_SENT") | G37: =IFERROR(__xludf.DUMMYFUNCTION("""COMPUTED_VALUE"""),"SUCCESS")
